<!-- <?xml version='1.0'?>
<sdf version='1.4'>
  <model name="my_robot">
  <static>true</static> 
  
          <link name='chassis'>
            <pose>0 0 .05 0 0 0</pose>

            <collision name='collision'>
              <geometry>
                <box>
                  <size>.4 .2 .1</size>
                </box>
              </geometry>
            </collision>

            <visual name='visual'>
              <geometry>
                <box>
                  <size>.4 .2 .1</size>
                </box>
              </geometry>
            </visual>
          </link>
          
          <link name='caster'>
            <collision name='caster_collision'>
            <pose>-0.15 0 -0.05 0 0 0</pose>
            <geometry>
                <sphere>
                <radius>.05</radius>
              </sphere>
            </geometry>

            <surface>
              <friction>
                <ode>
                  <mu>0</mu>
                  <mu2>0</mu2>
                  <slip1>1.0</slip1>
                  <slip2>1.0</slip2>
                </ode>
              </friction>
            </surface>
          </collision>

          <visual name='caster_visual'>
            <pose>-0.15 0 -0.05 0 0 0</pose>
            <geometry>
              <sphere>
                <radius>.05</radius>
              </sphere>
            </geometry>
          </visual>
            
          </link>
          
          <link name='arm 1'>
            <pose>0 0 .2 0 0 0</pose>

            <collision name='collision'>
              <geometry>
                <box>
                  <size>.1 .1 .05</size>
                </box>
              </geometry>
            </collision>

            <visual name='visual'>
              <geometry>
                <box>
                  <size>.1 .1 .05</size>
                </box>
              </geometry>
            </visual> 
          </link>
          
          <link name='arm 2'>
            <pose>0 0 .1 0 0 0</pose>
            <collision name='collision'>
              <geometry>
                <box>
                  <size>.05 .05 2</size>
                </box>
              </geometry>
            </collision>

            <visual name='visual'>
              <geometry>
                <box>
                  <size>.05 .05 2</size>
                </box>
              </geometry>
            </visual> 
          </link>
          
          <link name='arm 3'>
            <pose>0 0 2.25 0 0 0</pose>
            <collision name='collision'>
              <geometry>
                <box>
                  <size>.05 .05 1</size>
                </box>
              </geometry>
            </collision>

            <visual name='visual'>
              <geometry>
                <box>
                  <size>.05 .05 1</size>
                </box>
              </geometry>
            </visual> 
          </link>
          
          <link name='arm 4'>
            <pose>0 0 3.25 0 0 0</pose>

            <collision name='collision'>
              <geometry>
                <box>
                  <size>.05 .05 .5</size>
                </box>
              </geometry>
            </collision>

            <visual name='visual'>
              <geometry>
                <box>
                  <size>.05 .05 .5</size>
                </box>
              </geometry>
            </visual> 
            
          </link>
          
          
          <link name="left_wheel">
        <pose>0.1 0.13 0.1 0 1.5707 1.5707</pose>
        <collision name="collision">
          <geometry>
            <cylinder>
              <radius>.1</radius>
              <length>.05</length>
            </cylinder>
          </geometry>
        </collision>
        <visual name="visual">
          <geometry>
            <cylinder>
              <radius>.1</radius>
              <length>.05</length>
            </cylinder>
          </geometry>
        </visual>
      </link>
      
      <link name="right_wheel">
        <pose>0.1 -0.13 0.1 0 1.5707 1.5707</pose>
        <collision name="collision">
          <geometry>
            <cylinder>
              <radius>.1</radius>
              <length>.05</length>
            </cylinder>
          </geometry>
        </collision>
        <visual name="visual">
          <geometry>
            <cylinder>
              <radius>.1</radius>
              <length>.05</length>
            </cylinder>
          </geometry>
        </visual>
      </link>
  <joint type="revolute" name="left_wheel_hinge">
        <pose>0 0 -0.03 0 0 0</pose>
        <child>left_wheel</child>
        <parent>chassis</parent>
        <axis>
          <xyz>0 1 0</xyz>
        </axis>
      </joint>
      
      <joint type="revolute" name="arm1chassis_hinge">
        <pose>0 0 -0.03 0 0 0</pose>
        <child>arm 1</child>
        <parent>chassis</parent>
        <axis>
          <xyz>0 0 1</xyz>
        </axis>
      </joint>
      
      <joint type="revolute" name="arm1arm2_hinge">
        <pose>0 0 -0.03 0 0 0</pose>
        <child>arm 2</child>
        <parent>arm 1</parent>
        <axis>
          <xyz>1 0 0</xyz>
        </axis>
      </joint>
      
      <joint type="revolute" name="arm3arm2_hinge">
        <pose>0 0 -0.03 0 0 0</pose>
        <child>arm 3</child>
        <parent>arm 2</parent>
        <axis>
          <xyz>1 0 0</xyz>
        </axis>
      </joint>
      
      <joint type="revolute" name="arm4arm3_hinge">
        <pose>0 0 -0.03 0 0 0</pose>
        <child>arm 4</child>
        <parent>arm 3</parent>
        <axis>
          <xyz>1 0 0</xyz>
        </axis>
      </joint>

      <joint type="revolute" name="right_wheel_hinge">
        <pose>0 0 0.03 0 0 0</pose>
        <child>right_wheel</child>
        <parent>chassis</parent>
        <axis>
          <xyz>0 1 0</xyz>
        </axis>
      </joint>
  </model>
</sdf>-->

<!--With Hinges-->
<?xml version='1.0'?>
<sdf version='1.7'>
  <model name='my_robot'>
    <static>false</static>
    <link name='base'>
      <pose>0 0 0.05 0 -0 0</pose>
      <inertial>
        <mass>16000</mass>
        <inertia>
          <ixx>1053.33</ixx>
          <ixy>0</ixy>
          <ixz>0</ixz>
          <iyy>1053.33</iyy>
          <iyz>0</iyz>
          <izz>2000</izz>
        </inertia>
      </inertial>>
      <visual name='visual_base'>
        <geometry>
          <cylinder>
            <radius>0.5</radius>
            <length>0.1</length>
          </cylinder>
        </geometry> 
      </visual>
      <collision name='collision_base'>
        <geometry>
          <cylinder>
            <radius>0.5</radius>
            <length>0.1</length>
          </cylinder>
        </geometry>
      </collision>
    </link>
    
    <link name='first_arm'>
      <pose>0 0 0.125 0 -0 0</pose>
      <visual name='visual_first'>
        <geometry>
          <cylinder>
            <radius>0.1</radius>
            <length>0.05</length>
          </cylinder>
        </geometry>
      </visual>
      <collision name='collision_first'>
        <geometry>
          <cylinder>
            <radius>0.1</radius>
            <length>0.05</length>
          </cylinder>
        </geometry>   
      </collision>
      <inertial>
        <mass>5000</mass>
        <inertia>
          <ixx>17.7</ixx>
          <ixy>0</ixy>
          <ixz>0</ixz>
          <iyy>17.7</iyy>
          <iyz>0</iyz>
          <izz>25</izz>
        </inertia>
      </inertial>
    </link>
    
    <link name='second_arm'>
      <pose>0 0 1.15 0 0 0</pose>
      <visual name='visual_second'>
        <geometry>
          <cylinder>
            <radius>0.05</radius>
            <length>2</length>
          </cylinder>
        </geometry>
      </visual>
      <collision name='collision_second'>
        <geometry>
          <cylinder>
            <radius>0.05</radius>
            <length>2</length>
          </cylinder>
        </geometry>   
      </collision>
      <inertial>
        <mass>20</mass>
        <inertia>
          <ixx>321.5</ixx>
          <ixy>0</ixy>
          <ixz>0</ixz>
          <iyy>321.5</iyy>
          <iyz>0</iyz>
          <izz>0.025</izz>
        </inertia>
      </inertial>
    </link>

    <link name='second_hinge'>
      <pose>0.1 0 2.1 0 -1.571 0</pose>
      <visual name='visual_second_hinge'>
        <geometry>
          <cylinder>
            <radius>0.05</radius>
            <length>0.1</length>
          </cylinder>
        </geometry>
      </visual>
      <collision name='collision_second_hinge'>
        <geometry>
          <cylinder>
            <radius>0.05</radius>
            <length>0.1</length>
          </cylinder>
        </geometry>   
      </collision>
      <inertial>
        <mass>0.5</mass>
        <inertia>
          <ixx>0.177</ixx>
          <ixy>0</ixy>
          <ixz>0</ixz>
          <iyy>0.177</iyy>
          <iyz>0</iyz>
          <izz>0.25</izz>
        </inertia>
      </inertial>
    </link>

    <link name='third_arm'>
      <pose>0.2 0 2.55 0 0 0</pose>
      <visual name='visual_third'>
        <geometry>
          <cylinder>
            <radius>0.05</radius>
            <length>1</length>
          </cylinder>
        </geometry>
      </visual>
      <collision name='collision_third'>
        <geometry>
          <cylinder>
            <radius>0.05</radius>
            <length>1</length>
          </cylinder>
        </geometry>   
      </collision>
      <inertial>
        <mass>10</mass>
        <inertia>
          <ixx>37.5</ixx>
          <ixy>0</ixy>
          <ixz>0</ixz>
          <iyy>37.5</iyy>
          <iyz>0</iyz>
          <izz>0.003125</izz>
        </inertia>
      </inertial>
    </link>

    <link name='third_hinge'>
      <pose>0.3 0 3 0 -1.571 0</pose>
      <visual name='visual_third_hinge'>
        <geometry>
          <cylinder>
            <radius>0.05</radius>
            <length>0.1</length>
          </cylinder>
        </geometry>
      </visual>
      <collision name='collision_third_hinge'>
        <geometry>
          <cylinder>
            <radius>0.05</radius>
            <length>0.1</length>
          </cylinder>
        </geometry>   
      </collision>
      <inertial>
        <mass>0.5</mass>
        <inertia>
          <ixx>0.177</ixx>
          <ixy>0</ixy>
          <ixz>0</ixz>
          <iyy>0.177</iyy>
          <iyz>0</iyz>
          <izz>0.25</izz>
        </inertia>
      </inertial>
    </link>

    <link name='fourth_arm'>
      <pose>0.4 0 3.2 0 0 0</pose>
      <visual name='visual_fourth'>
        <geometry>
          <cylinder>
            <radius>0.05</radius>
            <length>0.5</length>
          </cylinder>
        </geometry>
      </visual>
      <collision name='collision_fourth'>
        <geometry>
          <cylinder>
            <radius>0.05</radius>
            <length>0.5</length>
          </cylinder>
        </geometry>   
      </collision>
      <inertial>
        <mass>5</mass>
        <inertia>
          <ixx>4.75</ixx>
          <ixy>0</ixy>
          <ixz>0</ixz>
          <iyy>4.75</iyy>
          <iyz>0</iyz>
          <izz>0.0004</izz>
        </inertia>
      </inertial>
    </link>

    <joint name='joint1' type='revolute'>
      <parent>base</parent>
      <child>first_arm</child>
      <pose>0 0 -0.025 0 -0 0</pose>
      <axis>
        <xyz>0 0 1</xyz>
      </axis>
    </joint>

    <joint name='joint2' type='revolute'>
      <parent>first_arm</parent>
      <child>second_arm</child>
      <pose>0 0 -1 0 -0 0</pose>
      <axis>
        <xyz>1 0 0</xyz>
      </axis>
    </joint>
    
    <joint name='joint3' type='fixed'>
      <parent>second_arm</parent>
      <child>second_hinge</child>
      <pose>0 0 0.05 0 -0 0</pose>
    </joint>
    
    <joint name='joint4' type='revolute'>
      <parent>second_hinge</parent>
      <child>third_arm</child>
      <pose>-0.05 0 -0.45 0 -0 0</pose>
      <axis>
        <xyz>1 0 0</xyz>
      </axis>
    </joint>
    
    <joint name='joint5' type='fixed'>
      <parent>third_arm</parent>
      <child>third_hinge</child>
      <pose>0 0 0.05 0 -0 0</pose>
    </joint>

    <joint name='joint6' type='revolute'>
      <parent>third_hinge</parent>
      <child>fourth_arm</child>
      <pose>-0.05 0 -0.2 0 -0 0</pose>
      <axis>
        <xyz>1 0 0</xyz>
      </axis>
    </joint>
  </model>
</sdf>


<!--Straight One-->
<!-- <?xml version='1.0'?>
<sdf version='1.7'>
  <model name='my_robot'>
    <static>false</static>
    <link name='base'>
      <pose>0 0 0.05 0 -0 0</pose>
      <visual name='visual_base'>
        <geometry>
          <cylinder>
            <radius>0.5</radius>
            <length>0.1</length>
          </cylinder>
        </geometry> 
      </visual>
      <collision name='collision_base'>
        <geometry>
          <cylinder>
            <radius>0.5</radius>
            <length>0.1</length>
          </cylinder>
        </geometry>
      </collision>
      <inertial>
        <mass>16000</mass>
        <inertia>
          <ixx>1053.33</ixx>
          <ixy>0</ixy>
          <ixz>0</ixz>
          <iyy>1053.33</iyy>
          <iyz>0</iyz>
          <izz>2000</izz>
        </inertia>
      </inertial>
    </link>
    
    <link name='first_arm'>
      <pose>0 0 0.125 0 -0 0</pose>
      <visual name='visual_first'>
        <geometry>
          <cylinder>
            <radius>0.1</radius>
            <length>0.05</length>
          </cylinder>
        </geometry>
      </visual>
      <collision name='collision_first'>
        <geometry>
          <cylinder>
            <radius>0.1</radius>
            <length>0.05</length>
          </cylinder>
        </geometry>   
      </collision>
      <inertial>
        <mass>5000</mass>
        <inertia>
          <ixx>17.7</ixx>
          <ixy>0</ixy>
          <ixz>0</ixz>
          <iyy>17.7</iyy>
          <iyz>0</iyz>
          <izz>25</izz>
        </inertia>
      </inertial>
    </link>
    
    <link name='second_arm'>
      <pose>0 0 1.15 0 0 0</pose>
      <visual name='visual_second'>
        <geometry>
          <cylinder>
            <radius>0.05</radius>
            <length>2</length>
          </cylinder>
        </geometry>
      </visual>
      <collision name='collision_second'>
        <geometry>
          <cylinder>
            <radius>0.05</radius>
            <length>2</length>
          </cylinder>
        </geometry>   
      </collision> 
      <inertial>
        <mass>20</mass>
        <inertia>
          <ixx>321.5</ixx>
          <ixy>0</ixy>
          <ixz>0</ixz>
          <iyy>321.5</iyy>
          <iyz>0</iyz>
          <izz>0.025</izz>
        </inertia>
      </inertial>
    </link>

    <link name='third_arm'>
      <pose>0 0 2.65 0 0 0</pose>
      <visual name='visual_third'>
        <geometry>
          <cylinder>
            <radius>0.05</radius>
            <length>1</length>
          </cylinder>
        </geometry>
      </visual>
      <collision name='collision_third'>
        <geometry>
          <cylinder>
            <radius>0.05</radius>
            <length>1</length>
          </cylinder>
        </geometry>     
      </collision>
    </link>

    <link name='fourth_arm'>
      <pose>0 0 3.4 0 0 0</pose>
      <visual name='visual'>
        <geometry>
          <cylinder>
            <radius>0.05</radius>
            <length>0.5</length>
          </cylinder>
        </geometry>   
        <pose>0 0 0 0 -0 0</pose>
      </visual>
      
      <collision name='collision_fourth'>
        <geometry>
          <cylinder>
            <radius>0.05</radius>
            <length>0.5</length>
          </cylinder>
        </geometry>     
      </collision>
    </link> 

    <joint name='joint1' type='revolute'>
      <parent>base</parent>
      <child>first_arm</child>
      <pose>0 0 -0.025 0 -0 0</pose>
      <axis>
        <xyz>0 0 1</xyz>
      </axis>
    </joint>
    
    <joint name='joint2' type='revolute'>
      <parent>first_arm</parent>
      <child>second_arm</child>
      <pose>0 0 -1 0 -0 0</pose>
      <axis>
        <xyz>1 0 0</xyz>
      </axis>
    </joint>
    
    <joint name='joint3' type='revolute'>
      <parent>second_arm</parent>
      <child>third_arm</child>
      <pose>0 0 -0.5 0 -0 0</pose>
      <axis>
        <xyz>1 0 0</xyz>
      </axis>
    </joint>
    
    <joint name='joint4' type='revolute'>
      <parent>third_arm</parent>
      <child>fourth_arm</child>
      <pose>0 0 -0.25 0 -0 0</pose>
      <axis>
        <xyz>1 0 0</xyz>
      </axis>
    </joint>
  </model>
</sdf> -->