<?xml version='1.0'?>
<sdf version='1.7'>
  <world name="default">

    <!-- Ground Plane -->
    <include>
      <uri>model://ground_plane</uri>
    </include>

    <include>
      <uri>model://sun</uri>
    </include>

  

   <model name='my_robot'>
    <static>false</static>
    <link name='base'>
      <pose>0 0 0.05 0 -0 0</pose>
      <visual name='visual_base'>
        <geometry>
          <cylinder>
            <radius>0.5</radius>
            <length>0.1</length>
          </cylinder>
        </geometry> 
      </visual>
      
      <collision name='collision_base'>
        <geometry>
          <cylinder>
            <radius>0.5</radius>
            <length>0.1</length>
          </cylinder>
        </geometry>
      </collision>

      <inertial>
        <mass>1000</mass>
        <!-- <inertia>
          <ixx>65.33</ixx>
          <ixy>0</ixy>
          <ixz>0</ixz>
          <iyy>65.33</iyy>
          <iyz>0</iyz>
          <izz>125</izz>
        </inertia> -->
      </inertial>
    </link>
    
    <link name='first_arm'>
      <pose>0 0 0.125 0 -0 0</pose>
      <visual name='visual_first'>
        <geometry>
          <cylinder>
            <radius>0.1</radius>
            <length>0.05</length>
          </cylinder>
        </geometry>
      </visual>
      
      <collision name='collision_first'>
        <geometry>
          <cylinder>
            <radius>0.1</radius>
            <length>0.05</length>
          </cylinder>
        </geometry>   
      </collision>

      <!-- <inertial>
        <mass>1000</mass>
        <inertia>
          <ixx>3.54</ixx>
          <ixy>0</ixy>
          <ixz>0</ixz>
          <iyy>3.54</iyy>
          <iyz>0</iyz>
          <izz>5</izz>
        </inertia>
      </inertial> -->
    </link>
    
    <link name='second_arm'>
      <pose>0 0 1.15 0 0 0</pose>
      <visual name='visual_second'>
        <geometry>
          <cylinder>
            <radius>0.05</radius>
            <length>2</length>
          </cylinder>
        </geometry>
      </visual>
      
      <collision name='collision_second'>
        <geometry>
          <cylinder>
            <radius>0.05</radius>
            <length>2</length>
          </cylinder>
        </geometry>   
      </collision>

      <!-- <inertial>
        <mass>2</mass>
        <inertia>
          <ixx>32.15</ixx>
          <ixy>0</ixy>
          <ixz>0</ixz>
          <iyy>32.15</iyy>
          <iyz>0</iyz>
          <izz>0.0025</izz>
        </inertia>
      </inertial> -->
    </link>

    <link name='third_arm'>
      <pose>0 0 2.65 0 0 0</pose>
      <visual name='visual_third'>
        <geometry>
          <cylinder>
            <radius>0.05</radius>
            <length>1</length>
          </cylinder>
        </geometry>
      </visual>
      <collision name='collision_third'>
        <geometry>
          <cylinder>
            <radius>0.05</radius>
            <length>1</length>
          </cylinder>
        </geometry>     
      </collision>
      <!-- <inertial>
        <mass>10</mass>
        <inertia>
          <ixx>37.5</ixx>
          <ixy>0</ixy>
          <ixz>0</ixz>
          <iyy>37.5</iyy>
          <iyz>0</iyz>
          <izz>0.003125</izz>
        </inertia>
      </inertial> -->
    </link>
    
    <link name='fourth_arm'>
      <pose>0 0 3.4 0 0 0</pose>
      <visual name='visual'>
        <geometry>
          <cylinder>
            <radius>0.05</radius>
            <length>0.5</length>
          </cylinder>
        </geometry>   
        <pose>0 0 0 0 -0 0</pose>
      </visual>
      
      <collision name='collision_fourth'>
        <geometry>
          <cylinder>
            <radius>0.05</radius>
            <length>0.5</length>
          </cylinder>
        </geometry>     
      </collision>

      <!-- <inertial> -->
        <!-- <mass>5</mass>
        <inertia>
          <ixx>4.75</ixx>
          <ixy>0</ixy>
          <ixz>0</ixz>
          <iyy>4.75</iyy>
          <iyz>0</iyz>
          <izz>0.0004</izz>
        </inertia>
      </inertial> -->
    </link>

    <joint name='joint1' type='revolute'>
      <parent>base</parent>
      <child>first_arm</child>
      <pose>0 0 -0.025 0 -0 0</pose>
      <axis>
        <xyz>0 0 1</xyz>
        <dynamics>
               <damping>2.0</damping>
                <friction>0.7</friction>
                </dynamics>
        <limit>
             <effort>100</effort>
          <velocity>1.0</velocity>
        </limit>
      </axis>
    </joint>
    
    <joint name='joint2' type='revolute'>
      <parent>first_arm</parent>
      <child>second_arm</child>
      <pose>0 0 -1 0 -0 0</pose>
      <axis>
        <xyz>1 0 0</xyz>
        <dynamics>
               <damping>2.0</damping>
                <friction>0.7</friction>
                </dynamics>
        <limit>
             <effort>100</effort>
          <velocity>1.0</velocity>
        </limit>
      </axis>
    </joint>
    
    <joint name='joint3' type='revolute'>
      <parent>second_arm</parent>
      <child>third_arm</child>
      <pose>0 0 -0.5 0 -0 0</pose>
      <axis>
        <xyz>1 0 0</xyz>
        <dynamics>
               <damping>2.0</damping>
                <friction>0.7</friction>
                </dynamics>
        <limit>
             <effort>100</effort>
          <velocity>1.0</velocity>
        </limit>
      </axis>
    </joint>
    
    <joint name='joint4' type='revolute'>
      <parent>third_arm</parent>
      <child>fourth_arm</child>
      <pose>0 0 -0.25 0 -0 0</pose>
      <axis>
        <xyz>1 0 0</xyz>
        <dynamics>
               <damping>2.0</damping>
                <friction>0.7</friction>
                </dynamics>
        <limit>
             <effort>100</effort>
          <velocity>1.0</velocity>
        </limit>
      </axis>
    </joint>

    <plugin name="joint_plugin" filename="libjoint_plugin.so"/>
    </model>      
  </world>
</sdf>